<?xml version="1.0" encoding="utf-8"?>
<!-- This URDF was automatically created by SolidWorks to URDF Exporter! Originally created by Stephen Brawner (brawner@gmail.com) 
     Commit Version: 1.6.0-4-g7f85cfe  Build Version: 1.6.7995.38578
     For more information, please see http://wiki.ros.org/sw_urdf_exporter -->
<robot
  name="全身URDF_第二版20250923.SLDASM">
  <link
    name="base_link">
    <inertial>
      <origin
        xyz="0.115505839285172 0.000224019396961841 -0.711928109214716"
        rpy="0 0 0" />
      <mass
        value="22.994615312442" />
      <inertia
        ixx="0.162595595787359"
        ixy="-0.000267119374700568"
        ixz="-5.5713327443289E-06"
        iyy="0.263916843694501"
        iyz="-1.94076863632574E-07"
        izz="0.321780925637394" />
    </inertial>
    <visual>
      <origin
        xyz="0 0 0"
        rpy="0 0 0" />
      <geometry>
        <mesh
          filename="package://全身URDF_第二版20250923.SLDASM/meshes/base_link.STL" />
      </geometry>
      <material
        name="">
        <color
          rgba="0.752941176470588 0.752941176470588 0.752941176470588 1" />
      </material>
    </visual>
    <collision>
      <origin
        xyz="0 0 0"
        rpy="0 0 0" />
      <geometry>
        <mesh
          filename="package://全身URDF_第二版20250923.SLDASM/meshes/base_link.STL" />
      </geometry>
    </collision>
  </link>
  <link
    name="left1">
    <inertial>
      <origin
        xyz="-9.76713916676086E-05 -6.57019998190345E-06 -0.000859562277853332"
        rpy="0 0 0" />
      <mass
        value="0.363631822542872" />
      <inertia
        ixx="0.000502502647135098"
        ixy="2.55924303894646E-10"
        ixz="5.3967162478879E-07"
        iyy="0.000165412153706733"
        iyz="2.25227095567257E-09"
        izz="0.000507191032007878" />
    </inertial>
    <visual>
      <origin
        xyz="0 0 0"
        rpy="0 0 0" />
      <geometry>
        <mesh
          filename="package://全身URDF_第二版20250923.SLDASM/meshes/left1.STL" />
      </geometry>
      <material
        name="">
        <color
          rgba="0.752941176470588 0.752941176470588 0.752941176470588 1" />
      </material>
    </visual>
    <collision>
      <origin
        xyz="0 0 0"
        rpy="0 0 0" />
      <geometry>
        <mesh
          filename="package://全身URDF_第二版20250923.SLDASM/meshes/left1.STL" />
      </geometry>
    </collision>
  </link>
  <joint
    name="left_joint_1"
    type="continuous">
    <origin
      xyz="0 0.233 0"
      rpy="-1.5708 0 0.11314" />
    <parent
      link="base_link" />
    <child
      link="left1" />
    <axis
      xyz="0.1129 0 0.99361" />
  </joint>
  <link
    name="left2">
    <inertial>
      <origin
        xyz="0.215643502935841 -0.00545561504339404 0.000901646051352623"
        rpy="0 0 0" />
      <mass
        value="0.453661925541928" />
      <inertia
        ixx="0.000510328001340655"
        ixy="2.09881445468802E-05"
        ixz="-3.75094052917034E-07"
        iyy="0.000627610410589083"
        iyz="-3.52126232924067E-07"
        izz="0.000393325605015094" />
    </inertial>
    <visual>
      <origin
        xyz="0 0 0"
        rpy="0 0 0" />
      <geometry>
        <mesh
          filename="package://全身URDF_第二版20250923.SLDASM/meshes/left2.STL" />
      </geometry>
      <material
        name="">
        <color
          rgba="0.752941176470588 0.752941176470588 0.752941176470588 1" />
      </material>
    </visual>
    <collision>
      <origin
        xyz="0 0 0"
        rpy="0 0 0" />
      <geometry>
        <mesh
          filename="package://全身URDF_第二版20250923.SLDASM/meshes/left2.STL" />
      </geometry>
    </collision>
  </link>
  <joint
    name="left_joint2"
    type="continuous">
    <origin
      xyz="0 0 0"
      rpy="-1.5708 0.11314 0" />
    <parent
      link="left1" />
    <child
      link="left2" />
    <axis
      xyz="0 0 1" />
  </joint>
  <link
    name="left3">
    <inertial>
      <origin
        xyz="0.0291881806808338 0.124867607466075 -3.63057387819943E-07"
        rpy="0 0 0" />
      <mass
        value="0.466600235297101" />
      <inertia
        ixx="0.000619376723298426"
        ixy="-6.43306365916747E-06"
        ixz="-4.99506998434334E-19"
        iyy="0.000307317504049883"
        iyz="7.29005338182977E-10"
        izz="0.000586669924778157" />
    </inertial>
    <visual>
      <origin
        xyz="0 0 0"
        rpy="0 0 0" />
      <geometry>
        <mesh
          filename="package://全身URDF_第二版20250923.SLDASM/meshes/left3.STL" />
      </geometry>
      <material
        name="">
        <color
          rgba="0.752941176470588 0.752941176470588 0.752941176470588 1" />
      </material>
    </visual>
    <collision>
      <origin
        xyz="0 0 0"
        rpy="0 0 0" />
      <geometry>
        <mesh
          filename="package://全身URDF_第二版20250923.SLDASM/meshes/left3.STL" />
      </geometry>
    </collision>
  </link>
  <joint
    name="left_joint3"
    type="continuous">
    <origin
      xyz="0.2657 0 0"
      rpy="0 0 0" />
    <parent
      link="left2" />
    <child
      link="left3" />
    <axis
      xyz="0 0 1" />
  </joint>
  <link
    name="left4">
    <inertial>
      <origin
        xyz="4.63912431447611E-06 0.00151980833933735 0.252014564653812"
        rpy="0 0 0" />
      <mass
        value="0.195613242375713" />
      <inertia
        ixx="0.000102554776637174"
        ixy="-1.08802160283991E-08"
        ixz="1.24469202232343E-08"
        iyy="5.18337746202779E-05"
        iyz="-1.30847483370749E-08"
        izz="0.000105562683793647" />
    </inertial>
    <visual>
      <origin
        xyz="0 0 0"
        rpy="0 0 0" />
      <geometry>
        <mesh
          filename="package://全身URDF_第二版20250923.SLDASM/meshes/left4.STL" />
      </geometry>
      <material
        name="">
        <color
          rgba="0.752941176470588 0.752941176470588 0.752941176470588 1" />
      </material>
    </visual>
    <collision>
      <origin
        xyz="0 0 0"
        rpy="0 0 0" />
      <geometry>
        <mesh
          filename="package://全身URDF_第二版20250923.SLDASM/meshes/left4.STL" />
      </geometry>
    </collision>
  </link>
  <joint
    name="left_joint4"
    type="continuous">
    <origin
      xyz="0.03 0 0"
      rpy="-1.5708 0 0" />
    <parent
      link="left3" />
    <child
      link="left4" />
    <axis
      xyz="0 0 1" />
  </joint>
  <link
    name="left5">
    <inertial>
      <origin
        xyz="-6.08015859882016E-11 0.0691724928061146 0.000628722967550122"
        rpy="0 0 0" />
      <mass
        value="0.161969401289855" />
      <inertia
        ixx="0.000105561803004323"
        ixy="-5.61257427034012E-15"
        ixz="2.85334263944639E-13"
        iyy="5.63327162643157E-05"
        iyz="-2.05656009879617E-08"
        izz="9.71327301603908E-05" />
    </inertial>
    <visual>
      <origin
        xyz="0 0 0"
        rpy="0 0 0" />
      <geometry>
        <mesh
          filename="package://全身URDF_第二版20250923.SLDASM/meshes/left5.STL" />
      </geometry>
      <material
        name="">
        <color
          rgba="0.752941176470588 0.752941176470588 0.752941176470588 1" />
      </material>
    </visual>
    <collision>
      <origin
        xyz="0 0 0"
        rpy="0 0 0" />
      <geometry>
        <mesh
          filename="package://全身URDF_第二版20250923.SLDASM/meshes/left5.STL" />
      </geometry>
    </collision>
  </link>
  <joint
    name="left_joint5"
    type="continuous">
    <origin
      xyz="0 0 0.264"
      rpy="1.5708 0 0" />
    <parent
      link="left4" />
    <child
      link="left5" />
    <axis
      xyz="0 0 1" />
  </joint>
  <link
    name="left6">
    <inertial>
      <origin
        xyz="-7.95512544726762E-10 -8.07188983229512E-05 0.165632931916017"
        rpy="0 0 0" />
      <mass
        value="0.237845160272616" />
      <inertia
        ixx="0.000101058944599506"
        ixy="2.90159556949526E-10"
        ixz="1.02513594857515E-09"
        iyy="0.000132525575104004"
        iyz="-6.56633341660212E-07"
        izz="0.000138731723169756" />
    </inertial>
    <visual>
      <origin
        xyz="0 0 0"
        rpy="0 0 0" />
      <geometry>
        <mesh
          filename="package://全身URDF_第二版20250923.SLDASM/meshes/left6.STL" />
      </geometry>
      <material
        name="">
        <color
          rgba="0.752941176470588 0.752941176470588 0.752941176470588 1" />
      </material>
    </visual>
    <collision>
      <origin
        xyz="0 0 0"
        rpy="0 0 0" />
      <geometry>
        <mesh
          filename="package://全身URDF_第二版20250923.SLDASM/meshes/left6.STL" />
      </geometry>
    </collision>
  </link>
  <joint
    name="left_joint6"
    type="continuous">
    <origin
      xyz="0 0 0"
      rpy="-1.5708 0 0" />
    <parent
      link="left5" />
    <child
      link="left6" />
    <axis
      xyz="0 0 1" />
  </joint>
  <link
    name="right1">
    <inertial>
      <origin
        xyz="4.00568467284756E-13 -6.5701997835621E-06 -0.000865093642478443"
        rpy="0 0 0" />
      <mass
        value="0.363631822542872" />
      <inertia
        ixx="0.000502441328473964"
        ixy="5.03718886370315E-16"
        ixz="-3.34876858946165E-11"
        iyy="0.000165412153706733"
        iyz="2.26676457568796E-09"
        izz="0.000507252350669012" />
    </inertial>
    <visual>
      <origin
        xyz="0 0 0"
        rpy="0 0 0" />
      <geometry>
        <mesh
          filename="package://全身URDF_第二版20250923.SLDASM/meshes/right1.STL" />
      </geometry>
      <material
        name="">
        <color
          rgba="0.752941176470588 0.752941176470588 0.752941176470588 1" />
      </material>
    </visual>
    <collision>
      <origin
        xyz="0 0 0"
        rpy="0 0 0" />
      <geometry>
        <mesh
          filename="package://全身URDF_第二版20250923.SLDASM/meshes/right1.STL" />
      </geometry>
    </collision>
  </link>
  <joint
    name="right_joint1"
    type="continuous">
    <origin
      xyz="0 -0.233 0"
      rpy="1.5708 0 0" />
    <parent
      link="base_link" />
    <child
      link="right1" />
    <axis
      xyz="0 0 1" />
  </joint>
  <link
    name="right2">
    <inertial>
      <origin
        xyz="0.215643502935895 -0.00545561504344039 0.000901646051581995"
        rpy="0 0 0" />
      <mass
        value="0.453661925541928" />
      <inertia
        ixx="0.000510328001340653"
        ixy="2.09881445468771E-05"
        ixz="-3.75094052915149E-07"
        iyy="0.000627610410589082"
        iyz="-3.52126232920351E-07"
        izz="0.000393325605015093" />
    </inertial>
    <visual>
      <origin
        xyz="0 0 0"
        rpy="0 0 0" />
      <geometry>
        <mesh
          filename="package://全身URDF_第二版20250923.SLDASM/meshes/right2.STL" />
      </geometry>
      <material
        name="">
        <color
          rgba="0.752941176470588 0.752941176470588 0.752941176470588 1" />
      </material>
    </visual>
    <collision>
      <origin
        xyz="0 0 0"
        rpy="0 0 0" />
      <geometry>
        <mesh
          filename="package://全身URDF_第二版20250923.SLDASM/meshes/right2.STL" />
      </geometry>
    </collision>
  </link>
  <joint
    name="right_joint2"
    type="continuous">
    <origin
      xyz="0 0 0"
      rpy="-1.5708 0 0" />
    <parent
      link="right1" />
    <child
      link="right2" />
    <axis
      xyz="0 0 1" />
  </joint>
  <link
    name="right3">
    <inertial>
      <origin
        xyz="0.0291881806808931 0.124867607466046 -3.63057168994985E-07"
        rpy="0 0 0" />
      <mass
        value="0.466600235297102" />
      <inertia
        ixx="0.000619376723298427"
        ixy="-6.43306365917314E-06"
        ixz="2.6159964858792E-19"
        iyy="0.000307317504049884"
        iyz="7.29005335970343E-10"
        izz="0.000586669924778159" />
    </inertial>
    <visual>
      <origin
        xyz="0 0 0"
        rpy="0 0 0" />
      <geometry>
        <mesh
          filename="package://全身URDF_第二版20250923.SLDASM/meshes/right3.STL" />
      </geometry>
      <material
        name="">
        <color
          rgba="0.752941176470588 0.752941176470588 0.752941176470588 1" />
      </material>
    </visual>
    <collision>
      <origin
        xyz="0 0 0"
        rpy="0 0 0" />
      <geometry>
        <mesh
          filename="package://全身URDF_第二版20250923.SLDASM/meshes/right3.STL" />
      </geometry>
    </collision>
  </link>
  <joint
    name="right_joint3"
    type="continuous">
    <origin
      xyz="0.2657 0 0"
      rpy="0 0 0" />
    <parent
      link="right2" />
    <child
      link="right3" />
    <axis
      xyz="0 0 1" />
  </joint>
  <link
    name="right4">
    <inertial>
      <origin
        xyz="4.63912434156555E-06 0.00151980808589869 0.252014564785898"
        rpy="0 0 0" />
      <mass
        value="0.195613241160616" />
      <inertia
        ixx="0.000102554778041048"
        ixy="-1.08802111516348E-08"
        ixz="1.24469202675681E-08"
        iyy="5.18337749764504E-05"
        iyz="-1.3084780773735E-08"
        izz="0.000105562682742727" />
    </inertial>
    <visual>
      <origin
        xyz="0 0 0"
        rpy="0 0 0" />
      <geometry>
        <mesh
          filename="package://全身URDF_第二版20250923.SLDASM/meshes/right4.STL" />
      </geometry>
      <material
        name="">
        <color
          rgba="0.752941176470588 0.752941176470588 0.752941176470588 1" />
      </material>
    </visual>
    <collision>
      <origin
        xyz="0 0 0"
        rpy="0 0 0" />
      <geometry>
        <mesh
          filename="package://全身URDF_第二版20250923.SLDASM/meshes/right4.STL" />
      </geometry>
    </collision>
  </link>
  <joint
    name="right_joint4"
    type="continuous">
    <origin
      xyz="0.03 0 0"
      rpy="-1.5708 0 0" />
    <parent
      link="right3" />
    <child
      link="right4" />
    <axis
      xyz="0 0 1" />
  </joint>
  <link
    name="right5">
    <inertial>
      <origin
        xyz="-6.07931482932145E-11 0.0691724928061056 0.000628722967537076"
        rpy="0 0 0" />
      <mass
        value="0.161969401289854" />
      <inertia
        ixx="0.000105561803004323"
        ixy="-5.61244755892541E-15"
        ixz="2.85334189154759E-13"
        iyy="5.63327162643155E-05"
        iyz="-2.0565600987986E-08"
        izz="9.71327301603901E-05" />
    </inertial>
    <visual>
      <origin
        xyz="0 0 0"
        rpy="0 0 0" />
      <geometry>
        <mesh
          filename="package://全身URDF_第二版20250923.SLDASM/meshes/right5.STL" />
      </geometry>
      <material
        name="">
        <color
          rgba="0.752941176470588 0.752941176470588 0.752941176470588 1" />
      </material>
    </visual>
    <collision>
      <origin
        xyz="0 0 0"
        rpy="0 0 0" />
      <geometry>
        <mesh
          filename="package://全身URDF_第二版20250923.SLDASM/meshes/right5.STL" />
      </geometry>
    </collision>
  </link>
  <joint
    name="right_joint5"
    type="continuous">
    <origin
      xyz="0 0 0.264"
      rpy="1.5708 0 0" />
    <parent
      link="right4" />
    <child
      link="right5" />
    <axis
      xyz="0 0 1" />
  </joint>
  <link
    name="right6">
    <inertial>
      <origin
        xyz="-7.95507659745454E-10 -8.0718898277099E-05 0.165632931916008"
        rpy="0 0 0" />
      <mass
        value="0.237845160272615" />
      <inertia
        ixx="0.000101058944599505"
        ixy="2.90159557535636E-10"
        ixz="1.02513594811499E-09"
        iyy="0.000132525575104003"
        iyz="-6.56633341660242E-07"
        izz="0.000138731723169754" />
    </inertial>
    <visual>
      <origin
        xyz="0 0 0"
        rpy="0 0 0" />
      <geometry>
        <mesh
          filename="package://全身URDF_第二版20250923.SLDASM/meshes/right6.STL" />
      </geometry>
      <material
        name="">
        <color
          rgba="0.752941176470588 0.752941176470588 0.752941176470588 1" />
      </material>
    </visual>
    <collision>
      <origin
        xyz="0 0 0"
        rpy="0 0 0" />
      <geometry>
        <mesh
          filename="package://全身URDF_第二版20250923.SLDASM/meshes/right6.STL" />
      </geometry>
    </collision>
  </link>
  <joint
    name="right_joint6"
    type="continuous">
    <origin
      xyz="0 0 0"
      rpy="-1.5708 0 0" />
    <parent
      link="right5" />
    <child
      link="right6" />
    <axis
      xyz="0 0 1" />
  </joint>
  <link
    name="neck1">
    <inertial>
      <origin
        xyz="-3.6376649408032E-05 -2.25242800393315E-05 -0.0192211205087707"
        rpy="0 0 0" />
      <mass
        value="0.100765421294758" />
      <inertia
        ixx="4.54180305176123E-05"
        ixy="-2.30135907516012E-09"
        ixz="2.13103657623337E-09"
        iyy="3.87413512951596E-05"
        iyz="-1.02281959214907E-06"
        izz="2.62046388990922E-05" />
    </inertial>
    <visual>
      <origin
        xyz="0 0 0"
        rpy="0 0 0" />
      <geometry>
        <mesh
          filename="package://全身URDF_第二版20250923.SLDASM/meshes/neck1.STL" />
      </geometry>
      <material
        name="">
        <color
          rgba="0.752941176470588 0.752941176470588 0.752941176470588 1" />
      </material>
    </visual>
    <collision>
      <origin
        xyz="0 0 0"
        rpy="0 0 0" />
      <geometry>
        <mesh
          filename="package://全身URDF_第二版20250923.SLDASM/meshes/neck1.STL" />
      </geometry>
    </collision>
  </link>
  <joint
    name="neck_joint1"
    type="continuous">
    <origin
      xyz="0.00025 0.0001 0.227"
      rpy="0 0 0" />
    <parent
      link="base_link" />
    <child
      link="neck1" />
    <axis
      xyz="0 0 1" />
  </joint>
  <link
    name="neck2">
    <inertial>
      <origin
        xyz="0.0144867346419351 -0.0762486021477659 -0.000654482077056723"
        rpy="0 0 0" />
      <mass
        value="0.0981686589230529" />
      <inertia
        ixx="5.71889070869724E-05"
        ixy="-1.30125104979847E-08"
        ixz="-4.51123435926596E-08"
        iyy="3.40991941293677E-05"
        iyz="8.02403599111442E-09"
        izz="2.75552620153822E-05" />
    </inertial>
    <visual>
      <origin
        xyz="0 0 0"
        rpy="0 0 0" />
      <geometry>
        <mesh
          filename="package://全身URDF_第二版20250923.SLDASM/meshes/neck2.STL" />
      </geometry>
      <material
        name="">
        <color
          rgba="0.752941176470588 0.752941176470588 0.752941176470588 1" />
      </material>
    </visual>
    <collision>
      <origin
        xyz="0 0 0"
        rpy="0 0 0" />
      <geometry>
        <mesh
          filename="package://全身URDF_第二版20250923.SLDASM/meshes/neck2.STL" />
      </geometry>
    </collision>
  </link>
  <joint
    name="neck_joint2"
    type="continuous">
    <origin
      xyz="0 0 0"
      rpy="-1.5708 0 0" />
    <parent
      link="neck1" />
    <child
      link="neck2" />
    <axis
      xyz="0 0 1" />
  </joint>
</robot>