<?xml version="1.0" ?>
<!-- =================================================================================== -->
<!-- |    This document was autogenerated by xacro from open_manipulator_p_with_gripper_robot.urdf.xacro | -->
<!-- |    EDITING THIS FILE BY HAND IS NOT RECOMMENDED                                 | -->
<!-- =================================================================================== -->
<robot name="open_manipulator_p_with_gripper">
  <material name="black">
    <color rgba="0.0 0.0 0.0 1.0"/>
  </material>
  <material name="blue">
    <color rgba="0.0 0.0 0.8 1.0"/>
  </material>
  <material name="green">
    <color rgba="0.0 0.8 0.0 1.0"/>
  </material>
  <material name="grey">
    <color rgba="0.5 0.5 0.5 1.0"/>
  </material>
  <material name="orange">
    <color rgba="1.0 0.4235294117647059 0.0392156862745098 1.0"/>
  </material>
  <material name="brown">
    <color rgba="0.8705882352941177 0.8117647058823529 0.7647058823529411 1.0"/>
  </material>
  <material name="red">
    <color rgba="0.8 0.0 0.0 1.0"/>
  </material>
  <material name="white">
    <color rgba="1.0 1.0 1.0 1.0"/>
  </material>
  <!-- World -->
  <gazebo reference="world"/>
  <!-- Link1 -->
  <RefLink ref="link1"/>
  <!-- Link2 -->
  <RefLink ref="link2"/>
  <!-- Link3 -->
  <RefLink ref="link3"/>
  <!-- Link4 -->
  <RefLink ref="link4"/>
  <!-- Link5 -->
  <RefLink ref="link5"/>
  <!-- Link6 -->
  <RefLink ref="link6"/>
  <!-- end_link -->
  <RefLink ref="end_link"/>
  <!-- gripper_main_link -->
  <RefLink ref="gripper_main_link"/>
  <!-- gripper_link -->
  <RefLink ref="gripper_link"/>
  <!-- gripper_sub_link -->
  <RefLink ref="gripper_sub_link"/>
  <!-- end_effector_link -->
  <gazebo reference="end_effector_link">
    <material>Gazebo/Red</material>
  </gazebo>
  <!-- ros_control plugin -->
  <gazebo>
    <plugin filename="libgazebo_ros_control.so" name="gazebo_ros_control">
      <robotSimType>gazebo_ros_control/DefaultRobotHWSim</robotSimType>
    </plugin>
  </gazebo>
  <gazebo>
    <!-- loading plugin: mimic joints works in gazebo now -->
    <plugin filename="libroboticsgroup_gazebo_mimic_joint_plugin.so" name="gazebo_gripper_ros_control">
      <joint>gripper</joint>
      <mimicJoint>gripper_sub</mimicJoint>
      <multiplier>1.0</multiplier>
      <offset>0.0</offset>
    </plugin>
  </gazebo>
  <!-- camera -->
  <gazebo reference="camera_link">
    <sensor name="intel_realsense_r200" type="camera">
      <update_rate>30.0</update_rate>
      <camera name="head">
        <horizontal_fov>1.02974</horizontal_fov>
        <image>
          <width>1920</width>
          <height>1080</height>
          <format>R8G8B8</format>
        </image>
        <clip>
          <near>0.02</near>
          <far>300</far>
        </clip>
        <noise>
          <type>gaussian</type>
          <!-- Noise is sampled independently per pixel on each frame.
               That pixel's noise value is added to each of its color
               channels, which at that point lie in the range [0,1]. -->
          <mean>0.0</mean>
          <stddev>0.007</stddev>
        </noise>
      </camera>
      <plugin filename="libgazebo_ros_camera.so" name="camera_controller">
        <alwaysOn>true</alwaysOn>
        <updateRate>0.0</updateRate>
        <cameraName>camera/color</cameraName>
        <imageTopicName>image_raw</imageTopicName>
        <cameraInfoTopicName>camera_info</cameraInfoTopicName>
        <frameName>camera_link</frameName>
        <hackBaseline>0.07</hackBaseline>
        <distortionK1>0.0</distortionK1>
        <distortionK2>0.0</distortionK2>
        <distortionK3>0.0</distortionK3>
        <distortionT1>0.0</distortionT1>
        <distortionT2>0.0</distortionT2>
      </plugin>
    </sensor>
  </gazebo>
  <transmission name="tran1">
    <type>transmission_interface/SimpleTransmission</type>
    <joint name="joint1">
      <hardwareInterface>hardware_interface/PositionJointInterface</hardwareInterface>
    </joint>
    <actuator name="motor1">
      <mechanicalReduction>1</mechanicalReduction>
    </actuator>
  </transmission>
  <transmission name="tran2">
    <type>transmission_interface/SimpleTransmission</type>
    <joint name="joint2">
      <hardwareInterface>hardware_interface/PositionJointInterface</hardwareInterface>
    </joint>
    <actuator name="motor2">
      <mechanicalReduction>1</mechanicalReduction>
    </actuator>
  </transmission>
  <transmission name="tran3">
    <type>transmission_interface/SimpleTransmission</type>
    <joint name="joint3">
      <hardwareInterface>hardware_interface/PositionJointInterface</hardwareInterface>
    </joint>
    <actuator name="motor3">
      <mechanicalReduction>1</mechanicalReduction>
    </actuator>
  </transmission>
  <transmission name="tran4">
    <type>transmission_interface/SimpleTransmission</type>
    <joint name="joint4">
      <hardwareInterface>hardware_interface/PositionJointInterface</hardwareInterface>
    </joint>
    <actuator name="motor4">
      <mechanicalReduction>1</mechanicalReduction>
    </actuator>
  </transmission>
  <transmission name="tran5">
    <type>transmission_interface/SimpleTransmission</type>
    <joint name="joint5">
      <hardwareInterface>hardware_interface/PositionJointInterface</hardwareInterface>
    </joint>
    <actuator name="motor5">
      <mechanicalReduction>1</mechanicalReduction>
    </actuator>
  </transmission>
  <transmission name="tran6">
    <type>transmission_interface/SimpleTransmission</type>
    <joint name="joint6">
      <hardwareInterface>hardware_interface/PositionJointInterface</hardwareInterface>
    </joint>
    <actuator name="motor6">
      <mechanicalReduction>1</mechanicalReduction>
    </actuator>
  </transmission>
  <transmission name="trangripper">
    <type>transmission_interface/SimpleTransmission</type>
    <joint name="gripper">
      <hardwareInterface>hardware_interface/EffortJointInterface</hardwareInterface>
    </joint>
    <actuator name="motorgripper">
      <mechanicalReduction>1</mechanicalReduction>
    </actuator>
  </transmission>
  <transmission name="trangripper_sub">
    <type>transmission_interface/SimpleTransmission</type>
    <joint name="gripper_sub">
      <hardwareInterface>hardware_interface/EffortJointInterface</hardwareInterface>
    </joint>
    <actuator name="motorgripper_sub">
      <mechanicalReduction>1</mechanicalReduction>
    </actuator>
  </transmission>
  <!-- link 1 -->
  <link name="link1">
    <visual>
      <origin rpy="0 0 0" xyz="0 0 0"/>
      <geometry>
        <mesh filename="/home/aiRobots/pybullet/open_manipulator_p_description/meshes/link1.stl" scale="0.001 0.001 0.001"/>
      </geometry>
      <material name="grey"/>
    </visual>
    <collision>
      <origin rpy="0 0 0" xyz="0 0 0"/>
      <geometry>
        <mesh filename="/home/aiRobots/pybullet/open_manipulator_p_description/meshes/link1.stl" scale="0.001 0.001 0.001"/>
      </geometry>
    </collision>
    <inertial>
      <origin rpy="0 0 0" xyz="0.00023 0.00000 0.06223"/>
      <mass value="0.85644"/>
      <inertia ixx="1.0" ixy="0.0" ixz="0.0" iyy="1.0" iyz="0.0" izz="1.0"/>
      <!--<inertia ixx="0.00121064" ixy="0.0" ixz="0.00001100" iyy="0.00120886" iyz="0.0" izz="0.00038103" />-->
    </inertial>
  </link>
  <!-- Joint 1 -->
  <joint name="joint1" type="revolute">
    <parent link="link1"/>
    <child link="link2"/>
    <origin rpy="0 0 0" xyz="0.0 0.0 0.126"/>
    <axis xyz="0 0 1"/>
    <limit effort="1000" lower="-1.5707963267948966" upper="1.5707963267948966" velocity="6.5"/>
    <dynamics damping="0.7"/>
  </joint>
  <!-- link 2 -->
  <link name="link2">
    <visual>
      <origin rpy="0 0 0" xyz="0 0 0"/>
      <geometry>
        <mesh filename="/home/aiRobots/pybullet/open_manipulator_p_description/meshes/link2.stl" scale="0.001 0.001 0.001"/>
      </geometry>
      <material name="grey"/>
    </visual>
    <collision>
      <origin rpy="0 0 0" xyz="0 0 0"/>
      <geometry>
        <mesh filename="/home/aiRobots/pybullet/open_manipulator_p_description/meshes/link2.stl" scale="0.001 0.001 0.001"/>
      </geometry>
    </collision>
    <inertial>
      <origin rpy="0 0 0" xyz="0.00000 0.00080 0.03183"/>
      <!--<origin xyz="0.00000 -0.06820 -0.00117" rpy="0 0 0"/>-->
      <mass value="0.94658"/>
      <inertia ixx="1.0" ixy="0.0" ixz="0.0" iyy="1.0" iyz="0.0" izz="1.0"/>
      <!--<inertia ixx="0.00152547" ixy="0.0" ixz="0.0" iyy="0.00045954" iyz="-0.00001086" izz="0.00151740" />-->
    </inertial>
  </link>
  <!-- Joint 2 -->
  <joint name="joint2" type="revolute">
    <parent link="link2"/>
    <child link="link3"/>
    <origin rpy="0 0 0" xyz="0.0 0.069 0.033"/>
    <axis xyz="0 1 0"/>
    <limit effort="1000" lower="-1.5707963267948966" upper="1.5707963267948966" velocity="6.5"/>
    <dynamics damping="0.7"/>
  </joint>
  <!-- link 3 -->
  <link name="link3">
    <visual>
      <origin rpy="0 0 0" xyz="0 0 0"/>
      <geometry>
        <mesh filename="/home/aiRobots/pybullet/open_manipulator_p_description/meshes/link3.stl" scale="0.001 0.001 0.001"/>
      </geometry>
      <material name="grey"/>
    </visual>
    <collision>
      <origin rpy="0 0 0" xyz="0 0 0"/>
      <geometry>
        <mesh filename="/home/aiRobots/pybullet/open_manipulator_p_description/meshes/link3.stl" scale="0.001 0.001 0.001"/>
      </geometry>
    </collision>
    <inertial>
      <origin rpy="0 0 0" xyz="0.01768 -0.06881 0.20524"/>
      <!--<origin xyz="-0.01232 -0.05731 -0.05876" rpy="0 0 0"/>-->
      <mass value="1.30260"/>
      <inertia ixx="1.0" ixy="0.0" ixz="0.0" iyy="1.0" iyz="0.0" izz="1.0"/>
      <!--<inertia ixx="0.01111021" ixy="0.00001331" ixz="-0.00134208" iyy="0.01046642" iyz="0.00016235" izz="0.00202081" />-->
    </inertial>
  </link>
  <!-- Joint 3 -->
  <joint name="joint3" type="revolute">
    <parent link="link3"/>
    <child link="link4"/>
    <origin rpy="0 0 0" xyz="0.03000 -0.01150 0.26400"/>
    <axis xyz="0 1 0"/>
    <limit effort="1000" lower="-1.5707963267948966" upper="1.5707963267948966" velocity="6.5"/>
    <dynamics damping="0.7"/>
  </joint>
  <!-- link 4 -->
  <link name="link4">
    <visual>
      <origin rpy="0 0 0" xyz="0 0 0"/>
      <geometry>
        <mesh filename="/home/aiRobots/pybullet/open_manipulator_p_description/meshes/link4.stl" scale="0.001 0.001 0.001"/>
      </geometry>
      <material name="grey"/>
    </visual>
    <collision>
      <origin rpy="0 0 0" xyz="0 0 0"/>
      <geometry>
        <mesh filename="/home/aiRobots/pybullet/open_manipulator_p_description/meshes/link4.stl" scale="0.001 0.001 0.001"/>
      </geometry>
    </collision>
    <inertial>
      <origin rpy="0 0 0" xyz="0.12475 -0.05716 0.02979"/>
      <!--<origin xyz="-0.07025 0.00034 -0.00021" rpy="0 0 0"/>-->
      <mass value="1.15977"/>
      <inertia ixx="1.0" ixy="0.0" ixz="0.0" iyy="1.0" iyz="0.0" izz="1.0"/>
      <!--<inertia ixx="0.00096726" ixy="0.00004383" ixz="-0.00002771" iyy="0.00318801" iyz="0.00000627" izz="0.00341484" />-->
    </inertial>
  </link>
  <!-- Joint 4 -->
  <joint name="joint4" type="revolute">
    <parent link="link4"/>
    <child link="link5"/>
    <origin rpy="0 0 0" xyz="0.19500 -0.05750 0.03000"/>
    <axis xyz="1 0 0"/>
    <limit effort="1000" lower="-1.5707963267948966" upper="1.5707963267948966" velocity="6.5"/>
    <dynamics damping="0.7"/>
  </joint>
  <!-- link 5 -->
  <link name="link5">
    <visual>
      <origin rpy="0 0 0" xyz="0 0 0"/>
      <geometry>
        <mesh filename="/home/aiRobots/pybullet/open_manipulator_p_description/meshes/link5.stl" scale="0.001 0.001 0.001"/>
      </geometry>
      <material name="grey"/>
    </visual>
    <collision>
      <origin rpy="0 0 0" xyz="0 0 0"/>
      <geometry>
        <mesh filename="/home/aiRobots/pybullet/open_manipulator_p_description/meshes/link5.stl" scale="0.001 0.001 0.001"/>
      </geometry>
    </collision>
    <inertial>
      <origin rpy="0 0 0" xyz="0.05642 -0.00217 0.00002"/>
      <!--<origin xyz="-0.00658 -0.04717 0.00002" rpy="0 0 0"/>-->
      <mass value="0.44688"/>
      <inertia ixx="1.0" ixy="0.0" ixz="0.0" iyy="1.0" iyz="0.0" izz="1.0"/>
      <!--<inertia ixx="0.00030285" ixy="0.00000761" ixz="0.00000031" iyy="0.00022339" iyz="-0.00000001" izz="0.00039766" />-->
    </inertial>
  </link>
  <!-- Joint 5 -->
  <joint name="joint5" type="revolute">
    <parent link="link5"/>
    <child link="link6"/>
    <origin rpy="0 0 0" xyz="0.06300 0.04500 0.00000"/>
    <axis xyz="0 1 0"/>
    <limit effort="1000" lower="-1.5707963267948966" upper="1.5707963267948966" velocity="6.5"/>
    <dynamics damping="0.7"/>
  </joint>
  <!-- link 6 -->
  <link name="link6">
    <visual>
      <origin rpy="0 0 0" xyz="0 0 0"/>
      <geometry>
        <mesh filename="/home/aiRobots/pybullet/open_manipulator_p_description/meshes/link6.stl" scale="0.001 0.001 0.001"/>
      </geometry>
      <material name="grey"/>
    </visual>
    <collision>
      <origin rpy="0 0 0" xyz="0 0 0"/>
      <geometry>
        <mesh filename="/home/aiRobots/pybullet/open_manipulator_p_description/meshes/link6.stl" scale="0.001 0.001 0.001"/>
      </geometry>
    </collision>
    <inertial>
      <origin rpy="0 0 0" xyz="0.06831 -0.04457 0.00000"/>
      <!--<origin xyz="-0.05469 0.00043 0.00000" rpy="0 0 0"/>-->
      <mass value="0.43273"/>
      <inertia ixx="1.0" ixy="0.0" ixz="0.0" iyy="1.0" iyz="0.0" izz="1.0"/>
      <!--<inertia ixx="0.00021512" ixy="0.00001009" ixz="0.00000000" iyy="0.00042827" iyz="0.00000000" izz="0.00051436" />-->
    </inertial>
  </link>
  <!-- Joint 6 -->
  <joint name="joint6" type="revolute">
    <parent link="link6"/>
    <child link="end_link"/>
    <origin rpy="0 0 0" xyz="0.12300 -0.04500 0.00000"/>
    <axis xyz="1 0 0"/>
    <limit effort="1000" lower="-1.5707963267948966" upper="1.5707963267948966" velocity="6.5"/>
    <dynamics damping="0.7"/>
  </joint>
  <!-- end link -->
  <link name="end_link">
    <visual>
      <origin rpy="0 0 0" xyz="0.0 0.0 0.0"/>
      <geometry>
        <mesh filename="/home/aiRobots/pybullet/open_manipulator_p_description/meshes/end_link.stl" scale="0.001 0.001 0.001"/>
      </geometry>
      <material name="grey"/>
    </visual>
    <collision>
      <origin rpy="0 0 0" xyz="0.0 0.0 0.0"/>
      <geometry>
        <mesh filename="/home/aiRobots/pybullet/open_manipulator_p_description/meshes/end_link.stl" scale="0.001 0.001 0.001"/>
      </geometry>
    </collision>
    <inertial>
      <origin rpy="0 0 0" xyz="0.00337 0.00000 0.00000"/>
      <mass value="0.01919"/>
      <inertia ixx="1.0" ixy="0.0" ixz="0.0" iyy="1.0" iyz="0.0" izz="1.0"/>
      <!--<inertia ixx="0.00000938" ixy="0.0" ixz="0.0" iyy="0.00000338" iyz="0.0" izz="0.00000635" />-->
    </inertial>
  </link>
  <!-- gripper main fixed joint-->
  <joint name="end_link_fixed" type="fixed">
    <parent link="end_link"/>
    <child link="gripper_main_link"/>
    <origin rpy="0 0 0" xyz="0.007 0.0 0.0"/>
  </joint>
  <!-- gripper main link -->
  <link name="gripper_main_link">
    <visual>
      <origin rpy="0 0 0" xyz="0 0 0"/>
      <geometry>
        <mesh filename="/home/aiRobots/pybullet/open_manipulator_p_description/meshes/gripper_main_link.stl" scale="0.001 0.001 0.001"/>
      </geometry>
      <material name="grey"/>
    </visual>
    <collision>
      <origin rpy="0 0 0" xyz="0 0 0"/>
      <geometry>
        <mesh filename="/home/aiRobots/pybullet/open_manipulator_p_description/meshes/gripper_main_link.stl" scale="0.001 0.001 0.001"/>
      </geometry>
    </collision>
    <inertial>
      <origin rpy="0 0 0" xyz="0.0 0.0 0.0"/>
      <mass value="0.509"/>
      <inertia ixx="1.0" ixy="0.0" ixz="0.0" iyy="1.0" iyz="0.0" izz="1.0"/>
    </inertial>
  </link>
  <!-- gripper joint -->
  <joint name="gripper" type="revolute">
    <axis xyz="0 0 1"/>
    <origin rpy="0 0 -0.4" xyz="0.0552 -0.0400 0"/>
    <parent link="gripper_main_link"/>
    <child link="gripper_link"/>
    <limit effort="1000" lower="0.0" upper="1.1" velocity="6.5"/>
    <dynamics damping="0.1" friction="0.0"/>
  </joint>
  <!-- gripper link -->
  <link name="gripper_link">
    <visual>
      <origin rpy="0 0 0" xyz="0 0 0"/>
      <geometry>
        <mesh filename="/home/aiRobots/pybullet/open_manipulator_p_description/meshes/gripper_link.stl" scale="0.001 0.001 0.001"/>
      </geometry>
      <material name="grey"/>
    </visual>
    <collision>
      <origin rpy="0 0 0" xyz="0 0 0"/>
      <geometry>
        <mesh filename="/home/aiRobots/pybullet/open_manipulator_p_description/meshes/gripper_link.stl" scale="0.001 0.001 0.001"/>
      </geometry>
      <material name="grey"/>
    </collision>
    <inertial>
      <origin rpy="0 0 0" xyz="0 0 0"/>
      <mass value="0.013"/>
      <inertia ixx="1.0" ixy="0.0" ixz="0.0" iyy="1.0" iyz="0.0" izz="1.0"/>
    </inertial>
  </link>
  <!-- gripper joint 1 -->
  <joint name="gripper_sub" type="revolute">
    <axis xyz="0 0 -1"/>
    <origin rpy="0 0 0.4" xyz="0.0552 0.0400 0"/>
    <parent link="gripper_main_link"/>
    <child link="gripper_sub_link"/>
    <limit effort="1000" lower="0.0" upper="1.1" velocity="6.5"/>
    <dynamics damping="0.1" friction="0.0"/>
    <mimic joint="gripper" multiplier="1"/>
  </joint>
  <!-- gripper 1 link -->
  <link name="gripper_sub_link">
    <visual>
      <origin rpy="0 0 0" xyz="0 0 0"/>
      <geometry>
        <mesh filename="/home/aiRobots/pybullet/open_manipulator_p_description/meshes/gripper_sub_link.stl" scale="0.001 0.001 0.001"/>
      </geometry>
      <material name="grey"/>
    </visual>
    <collision>
      <origin rpy="0 0 0" xyz="0 0 0"/>
      <geometry>
        <mesh filename="/home/aiRobots/pybullet/open_manipulator_p_description/meshes/gripper_sub_link.stl" scale="0.001 0.001 0.001"/>
      </geometry>
      <material name="grey"/>
    </collision>
    <inertial>
      <origin rpy="0 0 0" xyz="0 0 0"/>
      <mass value="0.013"/>
      <inertia ixx="1.0" ixy="0.0" ixz="0.0" iyy="1.0" iyz="0.0" izz="1.0"/>
    </inertial>
  </link>
  <!-- gripper main fixed joint-->
  <joint name="end_effector_joint" type="fixed">
    <parent link="gripper_main_link"/>
    <child link="end_effector_link"/>
    <origin rpy="0 0 0" xyz="0.14 0.0 0.0"/>
  </joint>
  <!-- End Effector -->
  <link name="end_effector_link">
    <visual>
      <origin rpy="0 0 0" xyz="0.0 0.0 0.0"/>
      <geometry>
        <box size="0.01 0.01 0.01"/>
      </geometry>
      <material name="red"/>
    </visual>
    <inertial>
      <origin rpy="0 0 0" xyz="0.0 0.0 0.0"/>
      <mass value="0.001"/>
      <inertia ixx="1.0" ixy="0.0" ixz="0.0" iyy="1.0" iyz="0.0" izz="1.0"/>
    </inertial>
  </link>
  <!-- Realsense Camera Joint Position -->
  <joint name="camera_joint" type="fixed">
    <axis xyz="0 1 0"/>
    <origin rpy="0 0 0" xyz="0.070 0.032 0.052"/>
    <parent link="gripper_main_link"/>
    <child link="camera_link"/>
  </joint>
  <link name="camera_link"/>
  <!-- World -->
  <link name="world"/>
  <!-- World fixed joint-->
  <joint name="world_fixed" type="fixed">
    <origin rpy="0 0 0" xyz="0 0 0"/>
    <parent link="world"/>
    <child link="link1"/>
  </joint>
</robot>
